Workbook

Sheet MASTER 50
A1: AKTIVNOST 1 – DIGITALIZACIJA POTI OB ŽICI: MASTER EVIDENCA 50 SPOMINSKIH OBELEŽIJ
A2: Delovna verzija V2. GPS koordinate so vnesene kot IZhodiščNI PRIBLIŽEK na osnovi javno dostopnih lokacijskih podatkov in prostorske presoje; pred objavo in namestitvijo QR-tablic jih je treba terensko uskladiti in strokovno preveriti.
A4: ID | B4: Etapa | C4: Odsek | D4: Vključitev | E4: Naziv obeležja | F4: Kraj / območje | G4: Vrsta obeležja | H4: GPS lat | I4: GPS lon | J4: GPS status | K4: EŠD | L4: EŠD status | M4: Kratka vsebinska iztočnica | N4: Ključna tema / osebe | O4: Vir 1 | P4: Vir 2 | Q4: Današnja foto | R4: Arhivska foto | S4: Pravice fotografij | T4: Kratko besedilo 800–1200 znakov | U4: Poglobljeno besedilo | V4: Video | W4: Avdio / podkast | X4: Kviz – 5 vprašanj | Y4: QR URL | Z4: QR generiran? | AA4: QR tablica nameščena? | AB4: Dovoljenje za QR | AC4: Strokovna verifikacija | AD4: Status izvedbe | AE4: Odgovorna oseba | AF4: Rok | AG4: Napredek % | AH4: Opombe
A5: NMZ-001 | B5: 7 | C5: Šmihel – Drska | D5: Osnovna pot | E5: Bunker na Drski | F5: Drska | G5: Bunker / obrambni objekt | H5: 45.7957 | I5: 15.1617 | J5: Izhodiščni približek – terensko uskladiti | L5: Za preverjanje | M5: Ohranjeni obrambni objekt, povezan z okupacijskim obročem okoli Novega mesta. | N5: Mesto v žici; okupacijski obrambni sistem | O5: https://www.zb-nob-nm.si/wp-content/uploads/2019/08/Novo-mesto-v-zici-Zlozenka.pdf | P5: https://partizanstvo.si/sl/podrobno/partizanskispomenik/6875/ | Q5: Ni začeto | R5: Ni začeto | S5: Ni začeto | T5: Ni začeto | U5: Ni začeto | V5: Ni začeto | W5: Ni začeto | X5: Ni začeto | Y5: =IF(A5="","",Nastavitve!$B$2&LOWER(A5)) | Z5: Ne | AA5: Ne | AB5: Za preverjanje | AC5: Za preverjanje | AD5: Predlog – preveriti | AG5: =ROUND((COUNTIF(Q5:X5,"Končano")+IF(Z5="Da",1,0)+IF(AA5="Da",1,0)+IF(AC5="Potrjeno",1,0))/11,2)
A6: NMZ-002 | B6: 4 | C6: Ragovo – Žabja vas | D6: Osnovna pot / bližina | E6: Spomenik padlim domačinom – Drejčetova pot | F6: Žabja vas | G6: Spomenik | H6: 45.7918 | I6: 15.1715 | J6: Izhodiščni približek – terensko uskladiti | K6: 15659 | L6: Vpisano | M6: Spomenik padlim domačinom na območju Žabje vasi. | N6: Lokalne žrtve NOB | O6: https://partizanstvo.si/ | P6: https://www.novomesto.si/dolenjski-uradni-list/dul-objave/2017110308141094/odlok_o_razglasitvi__nepremicnih_kulturnih_spomenikov_lokalnega_pomena_na_obmocju_mestne_obcine_novo_mesto/ | Q6: Ni začeto | R6: Ni začeto | S6: Ni začeto | T6: Ni začeto | U6: Ni začeto | V6: Ni začeto | W6: Ni začeto | X6: Ni začeto | Y6: =IF(A6="","",Nastavitve!$B$2&LOWER(A6)) | Z6: Ne | AA6: Ne | AB6: Za preverjanje | AC6: Za preverjanje | AD6: Predlog – preveriti | AG6: =ROUND((COUNTIF(Q6:X6,"Končano")+IF(Z6="Da",1,0)+IF(AA6="Da",1,0)+IF(AC6="Potrjeno",1,0))/11,2)
A7: NMZ-003 | B7: 4 | C7: Ragovo – Žabja vas | D7: Osnovna pot / bližina | E7: Grobnica padlih med NOB v Žabji vasi | F7: Žabja vas | G7: Grobnica | H7: 45.7909 | I7: 15.1706 | J7: Izhodiščni približek – terensko uskladiti | K7: 4216 | L7: Vpisano | M7: Grobnica padlih med NOB. | N7: Padli borci NOB | O7: https://partizanstvo.si/ | P7: https://www.novomesto.si/dolenjski-uradni-list/dul-objave/2017110308141094/odlok_o_razglasitvi__nepremicnih_kulturnih_spomenikov_lokalnega_pomena_na_obmocju_mestne_obcine_novo_mesto/ | Q7: Ni začeto | R7: Ni začeto | S7: Ni začeto | T7: Ni začeto | U7: Ni začeto | V7: Ni začeto | W7: Ni začeto | X7: Ni začeto | Y7: =IF(A7="","",Nastavitve!$B$2&LOWER(A7)) | Z7: Ne | AA7: Ne | AB7: Za preverjanje | AC7: Za preverjanje | AD7: Predlog – preveriti | AG7: =ROUND((COUNTIF(Q7:X7,"Končano")+IF(Z7="Da",1,0)+IF(AA7="Da",1,0)+IF(AC7="Potrjeno",1,0))/11,2)
A8: NMZ-004 | B8: 5 | C8: Žabja vas – Gotna vas | D8: Bližina poti | E8: Spominska plošča Valantičevi družini | F8: Kandija / Žabja vas | G8: Spominska plošča | H8: 45.7988 | I8: 15.1656 | J8: Izhodiščni približek – terensko uskladiti | L8: Za preverjanje | M8: Spomin na Valantičevo družino in civilne žrtve. | N8: Civilne žrtve; družinska zgodba | O8: https://partizanstvo.si/ | Q8: Ni začeto | R8: Ni začeto | S8: Ni začeto | T8: Ni začeto | U8: Ni začeto | V8: Ni začeto | W8: Ni začeto | X8: Ni začeto | Y8: =IF(A8="","",Nastavitve!$B$2&LOWER(A8)) | Z8: Ne | AA8: Ne | AB8: Za preverjanje | AC8: Za preverjanje | AD8: Predlog – preveriti | AG8: =ROUND((COUNTIF(Q8:X8,"Končano")+IF(Z8="Da",1,0)+IF(AA8="Da",1,0)+IF(AC8="Potrjeno",1,0))/11,2)
A9: NMZ-005 | B9: 5 | C9: Žabja vas – Gotna vas | D9: Bližina poti | E9: Grad Grm – plošča padlim gojencem kmetijske šole | F9: Grm | G9: Spominska plošča | H9: 45.7954 | I9: 15.1574 | J9: Izhodiščni približek – terensko uskladiti | L9: Za preverjanje | M9: Spominska plošča padlim gojencem kmetijske šole. | N9: Mladi; šolstvo; NOB | O9: https://partizanstvo.si/ | Q9: Ni začeto | R9: Ni začeto | S9: Ni začeto | T9: Ni začeto | U9: Ni začeto | V9: Ni začeto | W9: Ni začeto | X9: Ni začeto | Y9: =IF(A9="","",Nastavitve!$B$2&LOWER(A9)) | Z9: Ne | AA9: Ne | AB9: Za preverjanje | AC9: Za preverjanje | AD9: Predlog – preveriti | AG9: =ROUND((COUNTIF(Q9:X9,"Končano")+IF(Z9="Da",1,0)+IF(AA9="Da",1,0)+IF(AC9="Potrjeno",1,0))/11,2)
A10: NMZ-006 | B10: 5 | C10: Žabja vas – Gotna vas | D10: Bližina poti | E10: Grad Grm – plošča ob prvem praznovanju Dneva vstaje | F10: Grm | G10: Spominska plošča | H10: 45.7962 | I10: 15.1568 | J10: Izhodiščni približek – terensko uskladiti | L10: Za preverjanje | M10: Obeležje, povezano s prvim praznovanjem Dneva vstaje. | N10: Spomin; povojna kultura spominjanja | O10: https://partizanstvo.si/ | Q10: Ni začeto | R10: Ni začeto | S10: Ni začeto | T10: Ni začeto | U10: Ni začeto | V10: Ni začeto | W10: Ni začeto | X10: Ni začeto | Y10: =IF(A10="","",Nastavitve!$B$2&LOWER(A10)) | Z10: Ne | AA10: Ne | AB10: Za preverjanje | AC10: Za preverjanje | AD10: Predlog – preveriti | AG10: =ROUND((COUNTIF(Q10:X10,"Končano")+IF(Z10="Da",1,0)+IF(AA10="Da",1,0)+IF(AC10="Potrjeno",1,0))/11,2)
A11: NMZ-007 | B11: 5 | C11: Žabja vas – Gotna vas | D11: Bližina poti | E11: Plošča na nekdanjem Sokolskem domu | F11: Kandija / center | G11: Spominska plošča | H11: 45.8014 | I11: 15.1652 | J11: Izhodiščni približek – terensko uskladiti | L11: Za preverjanje | M11: NOB obeležje na nekdanjem Sokolskem domu. | N11: Odpor; organizirano delovanje | O11: https://partizanstvo.si/ | Q11: Ni začeto | R11: Ni začeto | S11: Ni začeto | T11: Ni začeto | U11: Ni začeto | V11: Ni začeto | W11: Ni začeto | X11: Ni začeto | Y11: =IF(A11="","",Nastavitve!$B$2&LOWER(A11)) | Z11: Ne | AA11: Ne | AB11: Za preverjanje | AC11: Za preverjanje | AD11: Predlog – preveriti | AG11: =ROUND((COUNTIF(Q11:X11,"Končano")+IF(Z11="Da",1,0)+IF(AA11="Da",1,0)+IF(AC11="Potrjeno",1,0))/11,2)
A12: NMZ-008 | B12: 8 | C12: Drska – Loka | D12: Bližina poti | E12: Plošča okrožni tehniki | F12: Center Novega mesta | G12: Spominska plošča | H12: 45.8032 | I12: 15.1676 | J12: Izhodiščni približek – terensko uskladiti | L12: Za preverjanje | M12: Spomin na ilegalno tiskarsko oziroma tehnično dejavnost. | N12: Ilegalna tehnika; odpor | O12: https://partizanstvo.si/ | Q12: Ni začeto | R12: Ni začeto | S12: Ni začeto | T12: Ni začeto | U12: Ni začeto | V12: Ni začeto | W12: Ni začeto | X12: Ni začeto | Y12: =IF(A12="","",Nastavitve!$B$2&LOWER(A12)) | Z12: Ne | AA12: Ne | AB12: Za preverjanje | AC12: Za preverjanje | AD12: Predlog – preveriti | AG12: =ROUND((COUNTIF(Q12:X12,"Končano")+IF(Z12="Da",1,0)+IF(AA12="Da",1,0)+IF(AC12="Potrjeno",1,0))/11,2)
A13: NMZ-009 | B13: 8 | C13: Drska – Loka | D13: Bližina poti | E13: Spomenik obešenima partizanoma | F13: Glavni trg | G13: Spomenik | H13: 45.8038 | I13: 15.1687 | J13: Izhodiščni približek – terensko uskladiti | K13: 8720 | L13: Vpisano | M13: Spomenik obešenima partizanoma na Glavnem trgu. | N13: Represija; talci; javne usmrtitve | O13: https://www.novomesto.si/dolenjski-uradni-list/dul-objave/2017110308141094/odlok_o_razglasitvi__nepremicnih_kulturnih_spomenikov_lokalnega_pomena_na_obmocju_mestne_obcine_novo_mesto/ | P13: https://partizanstvo.si/ | Q13: Ni začeto | R13: Ni začeto | S13: Ni začeto | T13: Ni začeto | U13: Ni začeto | V13: Ni začeto | W13: Ni začeto | X13: Ni začeto | Y13: =IF(A13="","",Nastavitve!$B$2&LOWER(A13)) | Z13: Ne | AA13: Ne | AB13: Za preverjanje | AC13: Za preverjanje | AD13: Predlog – preveriti | AG13: =ROUND((COUNTIF(Q13:X13,"Končano")+IF(Z13="Da",1,0)+IF(AA13="Da",1,0)+IF(AC13="Potrjeno",1,0))/11,2)
A14: NMZ-010 | B14: 8 | C14: Drska – Loka | D14: Bližina poti | E14: Spomeniški kompleks Na vratih / Loža herojev | F14: Rozmanova ulica | G14: Spomeniški kompleks | H14: 45.8044 | I14: 15.1682 | J14: Izhodiščni približek – terensko uskladiti | K14: 8722 | L14: Vpisano | M14: Osrednji mestni spominski kompleks NOB. | N14: Narodni heroji; kolektivni spomin | O14: https://www.novomesto.si/dolenjski-uradni-list/dul-objave/2017110308141094/odlok_o_razglasitvi__nepremicnih_kulturnih_spomenikov_lokalnega_pomena_na_obmocju_mestne_obcine_novo_mesto/ | P14: https://partizanstvo.si/ | Q14: Ni začeto | R14: Ni začeto | S14: Ni začeto | T14: Ni začeto | U14: Ni začeto | V14: Ni začeto | W14: Ni začeto | X14: Ni začeto | Y14: =IF(A14="","",Nastavitve!$B$2&LOWER(A14)) | Z14: Ne | AA14: Ne | AB14: Za preverjanje | AC14: Za preverjanje | AD14: Predlog – preveriti | AG14: =ROUND((COUNTIF(Q14:X14,"Končano")+IF(Z14="Da",1,0)+IF(AA14="Da",1,0)+IF(AC14="Potrjeno",1,0))/11,2)
A15: NMZ-011 | B15: 8 | C15: Drska – Loka | D15: Bližina poti | E15: Spominska avla Dolenjskega muzeja | F15: Center Novega mesta | G15: Muzejska spominska točka | H15: 45.8049 | I15: 15.1679 | J15: Izhodiščni približek – terensko uskladiti | L15: Za preverjanje | M15: Muzejska interpretacijska točka za zgodovino NOB na Dolenjskem. | N15: Muzejska interpretacija; zgodovinski viri | O15: https://www.dolenjskimuzej.si/ | Q15: Ni začeto | R15: Ni začeto | S15: Ni začeto | T15: Ni začeto | U15: Ni začeto | V15: Ni začeto | W15: Ni začeto | X15: Ni začeto | Y15: =IF(A15="","",Nastavitve!$B$2&LOWER(A15)) | Z15: Ne | AA15: Ne | AB15: Za preverjanje | AC15: Za preverjanje | AD15: Predlog – preveriti | AG15: =ROUND((COUNTIF(Q15:X15,"Končano")+IF(Z15="Da",1,0)+IF(AA15="Da",1,0)+IF(AC15="Potrjeno",1,0))/11,2)
A16: NMZ-012 | B16: 8 | C16: Drska – Loka | D16: Bližina poti | E16: Kip Josipa Broza Tita v vrtu Dolenjskega muzeja | F16: Center Novega mesta | G16: Kip / spomenik | H16: 45.8052 | I16: 15.1675 | J16: Izhodiščni približek – terensko uskladiti | L16: Za preverjanje | M16: Kip kot izhodišče za razpravo o vojni, povojnem času in kulturi spomina. | N16: Tito; povojni spomin | O16: https://www.dolenjskimuzej.si/ | Q16: Ni začeto | R16: Ni začeto | S16: Ni začeto | T16: Ni začeto | U16: Ni začeto | V16: Ni začeto | W16: Ni začeto | X16: Ni začeto | Y16: =IF(A16="","",Nastavitve!$B$2&LOWER(A16)) | Z16: Ne | AA16: Ne | AB16: Za preverjanje | AC16: Za preverjanje | AD16: Predlog – preveriti | AG16: =ROUND((COUNTIF(Q16:X16,"Končano")+IF(Z16="Da",1,0)+IF(AA16="Da",1,0)+IF(AC16="Potrjeno",1,0))/11,2)
A17: NMZ-013 | B17: 8 | C17: Drska – Loka | D17: Bližina poti | E17: Spominska plošča na sodišču | F17: Center Novega mesta | G17: Spominska plošča | H17: 45.8034 | I17: 15.1692 | J17: Izhodiščni približek – terensko uskladiti | L17: Za preverjanje | M17: NOB spominska plošča na stavbi sodišča. | N17: Represija; institucije; odpor | O17: https://partizanstvo.si/ | Q17: Ni začeto | R17: Ni začeto | S17: Ni začeto | T17: Ni začeto | U17: Ni začeto | V17: Ni začeto | W17: Ni začeto | X17: Ni začeto | Y17: =IF(A17="","",Nastavitve!$B$2&LOWER(A17)) | Z17: Ne | AA17: Ne | AB17: Za preverjanje | AC17: Za preverjanje | AD17: Predlog – preveriti | AG17: =ROUND((COUNTIF(Q17:X17,"Končano")+IF(Z17="Da",1,0)+IF(AA17="Da",1,0)+IF(AC17="Potrjeno",1,0))/11,2)
A18: NMZ-014 | B18: 8 | C18: Drska – Loka | D18: Bližina poti | E18: Plošča žrtvam bombardiranja Novega mesta | F18: Center / Kandija | G18: Spominska plošča | H18: 45.8019 | I18: 15.1668 | J18: Izhodiščni približek – terensko uskladiti | L18: Za preverjanje | M18: Spomin na civilne žrtve bombardiranja Novega mesta. | N18: Bombardiranje; civilne žrtve | O18: https://partizanstvo.si/ | Q18: Ni začeto | R18: Ni začeto | S18: Ni začeto | T18: Ni začeto | U18: Ni začeto | V18: Ni začeto | W18: Ni začeto | X18: Ni začeto | Y18: =IF(A18="","",Nastavitve!$B$2&LOWER(A18)) | Z18: Ne | AA18: Ne | AB18: Za preverjanje | AC18: Za preverjanje | AD18: Predlog – preveriti | AG18: =ROUND((COUNTIF(Q18:X18,"Končano")+IF(Z18="Da",1,0)+IF(AA18="Da",1,0)+IF(AC18="Potrjeno",1,0))/11,2)
A19: NMZ-015 | B19: 8 | C19: Drska – Loka | D19: Bližina poti | E19: Klet in spominska plošča talcem | F19: Ulica talcev 5 | G19: Spominska plošča / lokacija dogodka | H19: 45.8011 | I19: 15.1659 | J19: Izhodiščni približek – terensko uskladiti | K19: 8721 | L19: Vpisano | M19: Lokacija zapiranja oziroma trpljenja talcev in pripadajoče obeležje. | N19: Talci; okupacijsko nasilje | O19: https://www.novomesto.si/dolenjski-uradni-list/dul-objave/2017110308141094/odlok_o_razglasitvi__nepremicnih_kulturnih_spomenikov_lokalnega_pomena_na_obmocju_mestne_obcine_novo_mesto/ | P19: https://partizanstvo.si/ | Q19: Ni začeto | R19: Ni začeto | S19: Ni začeto | T19: Ni začeto | U19: Ni začeto | V19: Ni začeto | W19: Ni začeto | X19: Ni začeto | Y19: =IF(A19="","",Nastavitve!$B$2&LOWER(A19)) | Z19: Ne | AA19: Ne | AB19: Za preverjanje | AC19: Za preverjanje | AD19: Predlog – preveriti | AG19: =ROUND((COUNTIF(Q19:X19,"Končano")+IF(Z19="Da",1,0)+IF(AA19="Da",1,0)+IF(AC19="Potrjeno",1,0))/11,2)
A20: NMZ-016 | B20: 8 | C20: Drska – Loka | D20: Bližina poti | E20: Gimnazija – plošča trem herojem in 48 dijakom | F20: Center Novega mesta | G20: Spominska plošča | H20: 45.803 | I20: 15.17 | J20: Izhodiščni približek – terensko uskladiti | L20: Za preverjanje | M20: Šolsko obeležje trem herojem in padlim dijakom. | N20: Mladi; izobraževanje; odpor | O20: https://partizanstvo.si/ | Q20: Ni začeto | R20: Ni začeto | S20: Ni začeto | T20: Ni začeto | U20: Ni začeto | V20: Ni začeto | W20: Ni začeto | X20: Ni začeto | Y20: =IF(A20="","",Nastavitve!$B$2&LOWER(A20)) | Z20: Ne | AA20: Ne | AB20: Za preverjanje | AC20: Za preverjanje | AD20: Predlog – preveriti | AG20: =ROUND((COUNTIF(Q20:X20,"Končano")+IF(Z20="Da",1,0)+IF(AA20="Da",1,0)+IF(AC20="Potrjeno",1,0))/11,2)
A21: NMZ-017 | B21: 8 | C21: Drska – Loka | D21: Bližina poti | E21: Spomenik Katji Rupena | F21: OŠ Center | G21: Spomenik | H21: 45.8021 | I21: 15.169 | J21: Izhodiščni približek – terensko uskladiti | K21: 15654 | L21: Vpisano | M21: Spomenik Katji Rupena kot izhodišče za zgodbo o ženskah v odporu. | N21: Katja Rupena; ženske v odporu | O21: https://partizanstvo.si/ | P21: https://www.novomesto.si/dolenjski-uradni-list/dul-objave/2017110308141094/odlok_o_razglasitvi__nepremicnih_kulturnih_spomenikov_lokalnega_pomena_na_obmocju_mestne_obcine_novo_mesto/ | Q21: Ni začeto | R21: Ni začeto | S21: Ni začeto | T21: Ni začeto | U21: Ni začeto | V21: Ni začeto | W21: Ni začeto | X21: Ni začeto | Y21: =IF(A21="","",Nastavitve!$B$2&LOWER(A21)) | Z21: Ne | AA21: Ne | AB21: Za preverjanje | AC21: Za preverjanje | AD21: Predlog – preveriti | AG21: =ROUND((COUNTIF(Q21:X21,"Končano")+IF(Z21="Da",1,0)+IF(AA21="Da",1,0)+IF(AC21="Potrjeno",1,0))/11,2)
A22: NMZ-018 | B22: 8 | C22: Drska – Loka | D22: Bližina poti | E22: Plošča padlim mojstrom, pomočnikom in učencem | F22: Center Novega mesta | G22: Spominska plošča | H22: 45.804 | I22: 15.1696 | J22: Izhodiščni približek – terensko uskladiti | L22: Za preverjanje | M22: Spomin na padle iz obrtniškega oziroma poklicnega okolja. | N22: Delo; mladi; lokalna skupnost | O22: https://partizanstvo.si/ | Q22: Ni začeto | R22: Ni začeto | S22: Ni začeto | T22: Ni začeto | U22: Ni začeto | V22: Ni začeto | W22: Ni začeto | X22: Ni začeto | Y22: =IF(A22="","",Nastavitve!$B$2&LOWER(A22)) | Z22: Ne | AA22: Ne | AB22: Za preverjanje | AC22: Za preverjanje | AD22: Predlog – preveriti | AG22: =ROUND((COUNTIF(Q22:X22,"Končano")+IF(Z22="Da",1,0)+IF(AA22="Da",1,0)+IF(AC22="Potrjeno",1,0))/11,2)
A23: NMZ-019 | B23: 8 | C23: Drska – Loka | D23: Bližina poti | E23: Spominsko obeležje Stavka 1934 | F23: Novo mesto | G23: Spominsko obeležje | H23: 45.8037 | I23: 15.1705 | J23: Izhodiščni približek – terensko uskladiti | L23: Za preverjanje | M23: Predvojni družbeni in delavski kontekst kot uvod v radikalizacijo in odpor. | N23: Delavsko gibanje; predvojni kontekst | O23: https://partizanstvo.si/ | Q23: Ni začeto | R23: Ni začeto | S23: Ni začeto | T23: Ni začeto | U23: Ni začeto | V23: Ni začeto | W23: Ni začeto | X23: Ni začeto | Y23: =IF(A23="","",Nastavitve!$B$2&LOWER(A23)) | Z23: Ne | AA23: Ne | AB23: Za preverjanje | AC23: Za preverjanje | AD23: Predlog – preveriti | AG23: =ROUND((COUNTIF(Q23:X23,"Končano")+IF(Z23="Da",1,0)+IF(AA23="Da",1,0)+IF(AC23="Potrjeno",1,0))/11,2)
A24: NMZ-020 | B24: 1 | C24: Loka – Bršljin | D24: Bližina poti | E24: Grob borcev Cankarjeve brigade na Marofu | F24: Marof | G24: Grob / grobnica | H24: 45.8091 | I24: 15.1658 | J24: Izhodiščni približek – terensko uskladiti | L24: Za preverjanje | M24: Grob borcev Cankarjeve brigade. | N24: Cankarjeva brigada; padli borci | O24: https://partizanstvo.si/ | Q24: Ni začeto | R24: Ni začeto | S24: Ni začeto | T24: Ni začeto | U24: Ni začeto | V24: Ni začeto | W24: Ni začeto | X24: Ni začeto | Y24: =IF(A24="","",Nastavitve!$B$2&LOWER(A24)) | Z24: Ne | AA24: Ne | AB24: Za preverjanje | AC24: Za preverjanje | AD24: Predlog – preveriti | AG24: =ROUND((COUNTIF(Q24:X24,"Končano")+IF(Z24="Da",1,0)+IF(AA24="Da",1,0)+IF(AC24="Potrjeno",1,0))/11,2)
A25: NMZ-021 | B25: 1 | C25: Loka – Bršljin | D25: Osnovna pot / bližina | E25: Spominska plošča padlim iz Bršljina | F25: Bršljin | G25: Spominska plošča | H25: 45.8192 | I25: 15.1814 | J25: Izhodiščni približek – terensko uskladiti | K25: 15656 | L25: Vpisano | M25: Spominska plošča padlim domačinom iz Bršljina. | N25: Lokalni odpor; padli domačini | O25: https://partizanstvo.si/ | P25: https://www.novomesto.si/dolenjski-uradni-list/dul-objave/2017110308141094/odlok_o_razglasitvi__nepremicnih_kulturnih_spomenikov_lokalnega_pomena_na_obmocju_mestne_obcine_novo_mesto/ | Q25: Ni začeto | R25: Ni začeto | S25: Ni začeto | T25: Ni začeto | U25: Ni začeto | V25: Ni začeto | W25: Ni začeto | X25: Ni začeto | Y25: =IF(A25="","",Nastavitve!$B$2&LOWER(A25)) | Z25: Ne | AA25: Ne | AB25: Za preverjanje | AC25: Za preverjanje | AD25: Predlog – preveriti | AG25: =ROUND((COUNTIF(Q25:X25,"Končano")+IF(Z25="Da",1,0)+IF(AA25="Da",1,0)+IF(AC25="Potrjeno",1,0))/11,2)
A26: NMZ-022 | B26: 1 | C26: Loka – Bršljin | D26: Osnovna pot / bližina | E26: Spominska plošča Kastelčevi družini | F26: Bršljin | G26: Spominska plošča | H26: 45.82 | I26: 15.1821 | J26: Izhodiščni približek – terensko uskladiti | K26: 15655 | L26: Vpisano | M26: Spomin na Kastelčevo družino. | N26: Družinska zgodba; žrtve / odpor | O26: https://partizanstvo.si/ | P26: https://www.novomesto.si/dolenjski-uradni-list/dul-objave/2017110308141094/odlok_o_razglasitvi__nepremicnih_kulturnih_spomenikov_lokalnega_pomena_na_obmocju_mestne_obcine_novo_mesto/ | Q26: Ni začeto | R26: Ni začeto | S26: Ni začeto | T26: Ni začeto | U26: Ni začeto | V26: Ni začeto | W26: Ni začeto | X26: Ni začeto | Y26: =IF(A26="","",Nastavitve!$B$2&LOWER(A26)) | Z26: Ne | AA26: Ne | AB26: Za preverjanje | AC26: Za preverjanje | AD26: Predlog – preveriti | AG26: =ROUND((COUNTIF(Q26:X26,"Končano")+IF(Z26="Da",1,0)+IF(AA26="Da",1,0)+IF(AC26="Potrjeno",1,0))/11,2)
A27: NMZ-023 | B27: 1 | C27: Loka – Bršljin | D27: Osnovna pot / bližina | E27: Spominska plošča padlim železničarjem | F27: Železniška postaja Bršljin | G27: Spominska plošča | H27: 45.8184 | I27: 15.179 | J27: Izhodiščni približek – terensko uskladiti | L27: Za preverjanje | M27: Spominska plošča padlim železničarjem. | N27: Železničarji; odpor; logistika | O27: https://partizanstvo.si/ | Q27: Ni začeto | R27: Ni začeto | S27: Ni začeto | T27: Ni začeto | U27: Ni začeto | V27: Ni začeto | W27: Ni začeto | X27: Ni začeto | Y27: =IF(A27="","",Nastavitve!$B$2&LOWER(A27)) | Z27: Ne | AA27: Ne | AB27: Za preverjanje | AC27: Za preverjanje | AD27: Predlog – preveriti | AG27: =ROUND((COUNTIF(Q27:X27,"Končano")+IF(Z27="Da",1,0)+IF(AA27="Da",1,0)+IF(AC27="Potrjeno",1,0))/11,2)
A28: NMZ-024 | B28: 1 | C28: Loka – Bršljin | D28: Osnovna pot / bližina | E28: Spominska plošča na železniški kurilnici | F28: Bršljin | G28: Spominska plošča | H28: 45.8176 | I28: 15.18 | J28: Izhodiščni približek – terensko uskladiti | L28: Za preverjanje | M28: Obeležje železničarjem in vlogi železnice v času NOB. | N28: Železničarji; odpor | O28: https://partizanstvo.si/ | Q28: Ni začeto | R28: Ni začeto | S28: Ni začeto | T28: Ni začeto | U28: Ni začeto | V28: Ni začeto | W28: Ni začeto | X28: Ni začeto | Y28: =IF(A28="","",Nastavitve!$B$2&LOWER(A28)) | Z28: Ne | AA28: Ne | AB28: Za preverjanje | AC28: Za preverjanje | AD28: Predlog – preveriti | AG28: =ROUND((COUNTIF(Q28:X28,"Končano")+IF(Z28="Da",1,0)+IF(AA28="Da",1,0)+IF(AC28="Potrjeno",1,0))/11,2)
A29: NMZ-025 | B29: 2 | C29: Bršljin – Bučna vas | D29: Bližina poti | E29: Spomenik Milanu Majcnu | F29: Vojašnica / Bršljin | G29: Spomenik | H29: 45.821 | I29: 15.1849 | J29: Izhodiščni približek – terensko uskladiti | L29: Za preverjanje | M29: Spomenik Milanu Majcnu; preveriti režim dostopa zaradi lokacije. | N29: Milan Majcen; odpor | O29: https://partizanstvo.si/ | Q29: Ni začeto | R29: Ni začeto | S29: Ni začeto | T29: Ni začeto | U29: Ni začeto | V29: Ni začeto | W29: Ni začeto | X29: Ni začeto | Y29: =IF(A29="","",Nastavitve!$B$2&LOWER(A29)) | Z29: Ne | AA29: Ne | AB29: Za preverjanje | AC29: Za preverjanje | AD29: Predlog – preveriti | AG29: =ROUND((COUNTIF(Q29:X29,"Končano")+IF(Z29="Da",1,0)+IF(AA29="Da",1,0)+IF(AC29="Potrjeno",1,0))/11,2)
A30: NMZ-026 | B30: 2 | C30: Bršljin – Bučna vas | D30: Osnovna pot / bližina | E30: Spomenik NOB v Veliki Bučni vasi | F30: Velika Bučna vas | G30: Spomenik | H30: 45.8242 | I30: 15.1998 | J30: Izhodiščni približek – terensko uskladiti | K30: 8707 | L30: Vpisano | M30: Osrednje NOB obeležje v Veliki Bučni vasi. | N30: Lokalni odpor; padli | O30: https://www.novomesto.si/dolenjski-uradni-list/dul-objave/2017110308141094/odlok_o_razglasitvi__nepremicnih_kulturnih_spomenikov_lokalnega_pomena_na_obmocju_mestne_obcine_novo_mesto/ | P30: https://partizanstvo.si/ | Q30: Ni začeto | R30: Ni začeto | S30: Ni začeto | T30: Ni začeto | U30: Ni začeto | V30: Ni začeto | W30: Ni začeto | X30: Ni začeto | Y30: =IF(A30="","",Nastavitve!$B$2&LOWER(A30)) | Z30: Ne | AA30: Ne | AB30: Za preverjanje | AC30: Za preverjanje | AD30: Predlog – preveriti | AG30: =ROUND((COUNTIF(Q30:X30,"Končano")+IF(Z30="Da",1,0)+IF(AA30="Da",1,0)+IF(AC30="Potrjeno",1,0))/11,2)
A31: NMZ-027 | B31: 2 | C31: Bršljin – Bučna vas | D31: Osnovna pot / bližina | E31: Plošča Železničarski brigadi | F31: Velika Bučna vas | G31: Spominska plošča | H31: 45.8235 | I31: 15.2011 | J31: Izhodiščni približek – terensko uskladiti | L31: Za preverjanje | M31: Spominska točka, povezana z Železničarsko brigado. | N31: Železničarska brigada; organiziranje odpora | O31: https://partizanstvo.si/ | Q31: Ni začeto | R31: Ni začeto | S31: Ni začeto | T31: Ni začeto | U31: Ni začeto | V31: Ni začeto | W31: Ni začeto | X31: Ni začeto | Y31: =IF(A31="","",Nastavitve!$B$2&LOWER(A31)) | Z31: Ne | AA31: Ne | AB31: Za preverjanje | AC31: Za preverjanje | AD31: Predlog – preveriti | AG31: =ROUND((COUNTIF(Q31:X31,"Končano")+IF(Z31="Da",1,0)+IF(AA31="Da",1,0)+IF(AC31="Potrjeno",1,0))/11,2)
A32: NMZ-028 | B32: 3 | C32: Bučna vas – Ragovo | D32: Bližina poti | E32: Grobnica NOB na pokopališču Ločna | F32: Ločna | G32: Grobnica | H32: 45.8165 | I32: 15.1897 | J32: Izhodiščni približek – terensko uskladiti | K32: 4218 | L32: Vpisano | M32: Grobnica padlih iz časa NOB na pokopališču Ločna. | N32: Padli borci; spomin | O32: https://partizanstvo.si/ | P32: https://www.novomesto.si/dolenjski-uradni-list/dul-objave/2017110308141094/odlok_o_razglasitvi__nepremicnih_kulturnih_spomenikov_lokalnega_pomena_na_obmocju_mestne_obcine_novo_mesto/ | Q32: Ni začeto | R32: Ni začeto | S32: Ni začeto | T32: Ni začeto | U32: Ni začeto | V32: Ni začeto | W32: Ni začeto | X32: Ni začeto | Y32: =IF(A32="","",Nastavitve!$B$2&LOWER(A32)) | Z32: Ne | AA32: Ne | AB32: Za preverjanje | AC32: Za preverjanje | AD32: Predlog – preveriti | AG32: =ROUND((COUNTIF(Q32:X32,"Končano")+IF(Z32="Da",1,0)+IF(AA32="Da",1,0)+IF(AC32="Potrjeno",1,0))/11,2)
A33: NMZ-029 | B33: 3 | C33: Bučna vas – Ragovo | D33: Bližina poti | E33: Grob Antona Štrasnerja | F33: Ločna | G33: Grob | H33: 45.8174 | I33: 15.1905 | J33: Izhodiščni približek – terensko uskladiti | L33: Za preverjanje | M33: Grob Antona Štrasnerja, povezan z zgodbo obešanja leta 1943. | N33: Anton Štrasner; represija | O33: https://partizanstvo.si/ | Q33: Ni začeto | R33: Ni začeto | S33: Ni začeto | T33: Ni začeto | U33: Ni začeto | V33: Ni začeto | W33: Ni začeto | X33: Ni začeto | Y33: =IF(A33="","",Nastavitve!$B$2&LOWER(A33)) | Z33: Ne | AA33: Ne | AB33: Za preverjanje | AC33: Za preverjanje | AD33: Predlog – preveriti | AG33: =ROUND((COUNTIF(Q33:X33,"Končano")+IF(Z33="Da",1,0)+IF(AA33="Da",1,0)+IF(AC33="Potrjeno",1,0))/11,2)
A34: NMZ-030 | B34: 3 | C34: Bučna vas – Ragovo | D34: Bližina poti | E34: Spominska plošča padlim gasilcem | F34: Seidlova cesta | G34: Spominska plošča | H34: 45.8077 | I34: 15.1731 | J34: Izhodiščni približek – terensko uskladiti | L34: Za preverjanje | M34: Spomin na padle gasilce. | N34: Gasilstvo; lokalna skupnost; NOB | O34: https://partizanstvo.si/ | Q34: Ni začeto | R34: Ni začeto | S34: Ni začeto | T34: Ni začeto | U34: Ni začeto | V34: Ni začeto | W34: Ni začeto | X34: Ni začeto | Y34: =IF(A34="","",Nastavitve!$B$2&LOWER(A34)) | Z34: Ne | AA34: Ne | AB34: Za preverjanje | AC34: Za preverjanje | AD34: Predlog – preveriti | AG34: =ROUND((COUNTIF(Q34:X34,"Končano")+IF(Z34="Da",1,0)+IF(AA34="Da",1,0)+IF(AC34="Potrjeno",1,0))/11,2)
A35: NMZ-031 | B35: 6 | C35: Gotna vas – Šmihel | D35: Osnovna pot / bližina | E35: Grobnica NOB na pokopališču Šmihel | F35: Šmihel | G35: Grobnica | H35: 45.7898 | I35: 15.1562 | J35: Izhodiščni približek – terensko uskladiti | L35: Za preverjanje | M35: Osrednja grobnica NOB na pokopališču Šmihel. | N35: Padli borci; spomin | O35: https://partizanstvo.si/ | Q35: Ni začeto | R35: Ni začeto | S35: Ni začeto | T35: Ni začeto | U35: Ni začeto | V35: Ni začeto | W35: Ni začeto | X35: Ni začeto | Y35: =IF(A35="","",Nastavitve!$B$2&LOWER(A35)) | Z35: Ne | AA35: Ne | AB35: Za preverjanje | AC35: Za preverjanje | AD35: Predlog – preveriti | AG35: =ROUND((COUNTIF(Q35:X35,"Končano")+IF(Z35="Da",1,0)+IF(AA35="Da",1,0)+IF(AC35="Potrjeno",1,0))/11,2)
A36: NMZ-032 | B36: 6 | C36: Gotna vas – Šmihel | D36: Osnovna pot / bližina | E36: NOB obeležje pri OŠ Šmihel | F36: Šmihel | G36: Spominsko obeležje | H36: 45.7913 | I36: 15.1568 | J36: Izhodiščni približek – terensko uskladiti | L36: Za preverjanje | M36: Spominska točka ob šoli, primerna za pedagoško uporabo. | N36: Mladi; lokalna zgodovina | O36: https://partizanstvo.si/ | Q36: Ni začeto | R36: Ni začeto | S36: Ni začeto | T36: Ni začeto | U36: Ni začeto | V36: Ni začeto | W36: Ni začeto | X36: Ni začeto | Y36: =IF(A36="","",Nastavitve!$B$2&LOWER(A36)) | Z36: Ne | AA36: Ne | AB36: Za preverjanje | AC36: Za preverjanje | AD36: Predlog – preveriti | AG36: =ROUND((COUNTIF(Q36:X36,"Končano")+IF(Z36="Da",1,0)+IF(AA36="Da",1,0)+IF(AC36="Potrjeno",1,0))/11,2)
A37: NMZ-033 | B37: 6 | C37: Gotna vas – Šmihel | D37: Osnovna pot / bližina | E37: Spominski sklop NOB na pokopališču Šmihel | F37: Šmihel | G37: Spominski sklop | H37: 45.7904 | I37: 15.1552 | J37: Izhodiščni približek – terensko uskladiti | L37: Za preverjanje | M37: Več povezanih grobov in obeležij kot skupna učna točka. | N37: Padli borci; žrtve; spomin | O37: https://partizanstvo.si/ | Q37: Ni začeto | R37: Ni začeto | S37: Ni začeto | T37: Ni začeto | U37: Ni začeto | V37: Ni začeto | W37: Ni začeto | X37: Ni začeto | Y37: =IF(A37="","",Nastavitve!$B$2&LOWER(A37)) | Z37: Ne | AA37: Ne | AB37: Za preverjanje | AC37: Za preverjanje | AD37: Predlog – preveriti | AG37: =ROUND((COUNTIF(Q37:X37,"Končano")+IF(Z37="Da",1,0)+IF(AA37="Da",1,0)+IF(AC37="Potrjeno",1,0))/11,2)
A38: NMZ-034 | B38: 6 | C38: Gotna vas – Šmihel | D38: Bližina poti | E38: Valantičevo obeležje | F38: Šmihel | G38: Spominsko obeležje | H38: 45.7907 | I38: 15.156 | J38: Izhodiščni približek – terensko uskladiti | L38: Za preverjanje | M38: Delovna točka; potrebno je preveriti točen naziv, lokacijo in povezavo z Valantičevo družino. | N38: Valantičeva družina; lokalni spomin | O38: https://partizanstvo.si/ | Q38: Ni začeto | R38: Ni začeto | S38: Ni začeto | T38: Ni začeto | U38: Ni začeto | V38: Ni začeto | W38: Ni začeto | X38: Ni začeto | Y38: =IF(A38="","",Nastavitve!$B$2&LOWER(A38)) | Z38: Ne | AA38: Ne | AB38: Za preverjanje | AC38: Za preverjanje | AD38: Predlog – preveriti | AG38: =ROUND((COUNTIF(Q38:X38,"Končano")+IF(Z38="Da",1,0)+IF(AA38="Da",1,0)+IF(AC38="Potrjeno",1,0))/11,2)
A39: NMZ-035 | B39: 6 | C39: Gotna vas – Šmihel | D39: Osnovna pot / bližina | E39: Spomenik NOB pri sv. Roku | F39: Gotna vas | G39: Spomenik | H39: 45.7862 | I39: 15.1491 | J39: Izhodiščni približek – terensko uskladiti | K39: 4219 | L39: Vpisano | M39: Spomenik NOB pri sv. Roku. | N39: Lokalni odpor; spomin | O39: https://www.novomesto.si/dolenjski-uradni-list/dul-objave/2017110308141094/odlok_o_razglasitvi__nepremicnih_kulturnih_spomenikov_lokalnega_pomena_na_obmocju_mestne_obcine_novo_mesto/ | P39: https://partizanstvo.si/ | Q39: Ni začeto | R39: Ni začeto | S39: Ni začeto | T39: Ni začeto | U39: Ni začeto | V39: Ni začeto | W39: Ni začeto | X39: Ni začeto | Y39: =IF(A39="","",Nastavitve!$B$2&LOWER(A39)) | Z39: Ne | AA39: Ne | AB39: Za preverjanje | AC39: Za preverjanje | AD39: Predlog – preveriti | AG39: =ROUND((COUNTIF(Q39:X39,"Končano")+IF(Z39="Da",1,0)+IF(AA39="Da",1,0)+IF(AC39="Potrjeno",1,0))/11,2)
A40: NMZ-036 | B40: 2 | C40: Bršljin – Bučna vas | D40: Razširjeni zahodni krak | E40: Spomenik aktivistu Antonu Čampi | F40: Prečna | G40: Spomenik | H40: 45.8438 | I40: 15.1016 | J40: Izhodiščni približek – terensko uskladiti | L40: Za preverjanje | M40: Spomenik aktivistu Antonu Čampi. | N40: Anton Čampa; aktivizem / odpor | O40: https://partizanstvo.si/sl/podrobno/partizanskispomenik/4642/ | Q40: Ni začeto | R40: Ni začeto | S40: Ni začeto | T40: Ni začeto | U40: Ni začeto | V40: Ni začeto | W40: Ni začeto | X40: Ni začeto | Y40: =IF(A40="","",Nastavitve!$B$2&LOWER(A40)) | Z40: Ne | AA40: Ne | AB40: Za preverjanje | AC40: Za preverjanje | AD40: Predlog – preveriti | AG40: =ROUND((COUNTIF(Q40:X40,"Končano")+IF(Z40="Da",1,0)+IF(AA40="Da",1,0)+IF(AC40="Potrjeno",1,0))/11,2)
A41: NMZ-037 | B41: 2 | C41: Bršljin – Bučna vas | D41: Razširjeni zahodni krak | E41: Grob s spomenikom štirim talcem | F41: Prečna | G41: Grob / spomenik | H41: 45.8444 | I41: 15.1028 | J41: Izhodiščni približek – terensko uskladiti | L41: Za preverjanje | M41: Grob in spomenik štirim talcem. | N41: Talci; okupacijsko nasilje | O41: https://partizanstvo.si/ | Q41: Ni začeto | R41: Ni začeto | S41: Ni začeto | T41: Ni začeto | U41: Ni začeto | V41: Ni začeto | W41: Ni začeto | X41: Ni začeto | Y41: =IF(A41="","",Nastavitve!$B$2&LOWER(A41)) | Z41: Ne | AA41: Ne | AB41: Za preverjanje | AC41: Za preverjanje | AD41: Predlog – preveriti | AG41: =ROUND((COUNTIF(Q41:X41,"Končano")+IF(Z41="Da",1,0)+IF(AA41="Da",1,0)+IF(AC41="Potrjeno",1,0))/11,2)
...

Sheet Nastavitve
A1: NASTAVITVE PLATFORME | B1: Vrednost
A2: Osnovni URL QR | B2: https://novomestovzici.si/
A3: Ciljno št. obeležij | B3: 50
A4: Projekt | B4: Nevarnosti vzpona neonacizma in fašizma
A5: Aktivnost | B5: A1 – Digitalizacija Poti ob žici

Sheet Šifranti
A1: Vsebinski status | B1: Da/Ne | C1: GPS status | D1: EŠD status | E1: Dovoljenje QR | F1: Strokovna verifikacija | G1: Status izvedbe | H1: Vključitev
A2: Ni začeto | B2: Da | C2: Za preverjanje | D2: Za preverjanje | E2: Za preverjanje | F2: Za preverjanje | G2: Predlog – preveriti | H2: Osnovna pot
A3: V pripravi | B3: Ne | C3: Terensko izmerjeno | D3: Vpisano | E3: Pridobljeno | F3: V pregledu | G3: Potrjeno za vključitev | H3: Osnovna pot / bližina
A4: Za preverjanje | C4: Preverjeno v GIS | D4: Ni EŠD | E4: Ni potrebno | F4: Potrjeno | G4: Terenski popis | H4: Bližina poti
A5: Končano | D5: Ni relevantno | E5: Zavrnjeno | F5: Potrebni popravki | G5: V pripravi vsebin | H5: Razširjeni zahodni krak
A6: Ni potrebno | G6: V tehnični pripravi | H6: Razširjeni severni krak
G7: Objavljeno | H7: Razširjeni severovzhodni krak
G8: Izločeno / zamenjano | H8: Razširjeni vzhodni krak

Sheet Etape
A1: 8 ETAP DIGITALNE UČNE POTI – OPERATIVNA RAZPOREDITEV
A3: Etapa | B3: Odsek | C3: Osnovni fokus | D3: Št. točk v MASTER | E3: Razširjeni kraki | F3: Terenski popis | G3: Strokovni pregled | H3: Opomba
A4: 1 | B4: Loka – Bršljin | C4: Bršljin, železnica, Marof | D4: =COUNTIF('MASTER 50'!$B$5:$B$54,A4) | E4: – | F4: Ni začeto | G4: Ni začeto | H4: Preveriti natančen potek trase in dostop do železniških točk.
A5: 2 | B5: Bršljin – Bučna vas | C5: Bršljin, Bučna vas | D5: =COUNTIF('MASTER 50'!$B$5:$B$54,A5) | E5: Prečna, Češča vas | F5: Ni začeto | G5: Ni začeto | H5: Razširjeni zahodni krak je operativno pripisan etapi 2.
A6: 3 | B6: Bučna vas – Ragovo | C6: Ločna, severni rob mesta | D6: =COUNTIF('MASTER 50'!$B$5:$B$54,A6) | E6: Dolenje Kamence, Kuzarjev Kal, Trška Gora | F6: Ni začeto | G6: Ni začeto | H6: Razširitve je treba GIS preveriti glede smiselne povezave.
A7: 4 | B7: Ragovo – Žabja vas | C7: Ragovo, Žabja vas | D7: =COUNTIF('MASTER 50'!$B$5:$B$54,A7) | E7: Smolenja vas, Mali Slatnik, Otočec, Zagrad | F7: Ni začeto | G7: Ni začeto | H7: Vzhodni krak ni del osnovne 12-km trase.
A8: 5 | B8: Žabja vas – Gotna vas | C8: Žabja vas, Grm, Kandija | D8: =COUNTIF('MASTER 50'!$B$5:$B$54,A8) | E8: – | F8: Ni začeto | G8: Ni začeto | H8: Močna pedagoška etapa z več šolskimi in civilnimi zgodbami.
A9: 6 | B9: Gotna vas – Šmihel | C9: Gotna vas, Šmihel | D9: =COUNTIF('MASTER 50'!$B$5:$B$54,A9) | E9: – | F9: Ni začeto | G9: Ni začeto | H9: Pokopališče Šmihel je možno obravnavati kot en sklop ali več ločenih točk.
A10: 7 | B10: Šmihel – Drska | C10: Drska | D10: =COUNTIF('MASTER 50'!$B$5:$B$54,A10) | E10: – | F10: Ni začeto | G10: Ni začeto | H10: Ključna točka: bunker in interpretacija mesta v žici.
A11: 8 | B11: Drska – Loka | C11: Mestno jedro | D11: =COUNTIF('MASTER 50'!$B$5:$B$54,A11) | E11: – | F11: Ni začeto | G11: Ni začeto | H11: Najgostejši sklop mestnih spominskih točk.

Sheet Dashboard
A1: AKTIVNOST 1 – NADZORNA PLOŠČA DIGITALIZACIJE
A3: Kazalnik | B3: Vrednost | D3: Etapa | E3: Št. točk | G3: Status izvedbe | H3: Št.
A4: Skupaj obeležij | B4: =COUNTA('MASTER 50'!A5:A54) | D4: 1 | E4: =COUNTIF('MASTER 50'!$B$5:$B$54,D4) | G4: Predlog – preveriti | H4: =COUNTIF('MASTER 50'!$AD$5:$AD$54,G4)
A5: GPS terensko/GIS preverjen | B5: =COUNTIF('MASTER 50'!J5:J54,"Terensko izmerjeno")+COUNTIF('MASTER 50'!J5:J54,"Preverjeno v GIS") | D5: 2 | E5: =COUNTIF('MASTER 50'!$B$5:$B$54,D5) | G5: Potrjeno za vključitev | H5: =COUNTIF('MASTER 50'!$AD$5:$AD$54,G5)
A6: EŠD vpisan | B6: =COUNTIF('MASTER 50'!L5:L54,"Vpisano") | D6: 3 | E6: =COUNTIF('MASTER 50'!$B$5:$B$54,D6) | G6: Terenski popis | H6: =COUNTIF('MASTER 50'!$AD$5:$AD$54,G6)
A7: Današnja foto končana | B7: =COUNTIF('MASTER 50'!Q5:Q54,"Končano") | D7: 4 | E7: =COUNTIF('MASTER 50'!$B$5:$B$54,D7) | G7: V pripravi vsebin | H7: =COUNTIF('MASTER 50'!$AD$5:$AD$54,G7)
A8: Kratko besedilo končano | B8: =COUNTIF('MASTER 50'!T5:T54,"Končano") | D8: 5 | E8: =COUNTIF('MASTER 50'!$B$5:$B$54,D8) | G8: V tehnični pripravi | H8: =COUNTIF('MASTER 50'!$AD$5:$AD$54,G8)
A9: Kviz končan | B9: =COUNTIF('MASTER 50'!X5:X54,"Končano") | D9: 6 | E9: =COUNTIF('MASTER 50'!$B$5:$B$54,D9) | G9: Objavljeno | H9: =COUNTIF('MASTER 50'!$AD$5:$AD$54,G9)
A10: QR generiran | B10: =COUNTIF('MASTER 50'!Z5:Z54,"Da") | D10: 7 | E10: =COUNTIF('MASTER 50'!$B$5:$B$54,D10) | G10: Izločeno / zamenjano | H10: =COUNTIF('MASTER 50'!$AD$5:$AD$54,G10)
A11: QR tablica nameščena | B11: =COUNTIF('MASTER 50'!AA5:AA54,"Da") | D11: 8 | E11: =COUNTIF('MASTER 50'!$B$5:$B$54,D11)
A12: Objavljeno | B12: =COUNTIF('MASTER 50'!AD5:AD54,"Objavljeno")

Sheet Navodila
A1: NAVODILA ZA UPORABO MASTER EVIDENCE
A3: Korak | B3: Kaj naredimo | C3: Pravilo
A4: 1 | B4: Terenski popis vseh 50 kandidatov | C4: Vpiši GPS lat/lon, fotografiraj stanje, preveri fizični dostop in možnost QR tablice.
A5: 2 | B5: Preverjanje naziva in EŠD | C5: Pred izdelavo vsebine potrdi uradni naziv, EŠD in tip dediščine v RKD/ZVKDS oziroma pri strokovnem partnerju.
A6: 3 | B6: Izbor končnih 50 | C6: Status 'Potrjeno za vključitev' pomeni, da točka ostane v projektu. Izločene točke se zamenjajo, ID pa se ne reciklira brez zapisa v opombi.
A7: 4 | B7: Fotografije | C7: Za vsako točko ciljaj najmanj 1 kakovostno današnjo fotografijo in, kjer je mogoče, 1 arhivsko. Evidentiraj pravice.
A8: 5 | B8: Vsebine | C8: Minimalni paket: kratko besedilo 800–1200 znakov, poglobljeno besedilo, video, avdio/podkast in kviz s 5 vprašanji.
A9: 6 | B9: QR | C9: QR URL se avtomatsko sestavi iz osnovnega URL v zavihku Nastavitve + ID točke. Osnovni URL lahko kasneje zamenjaš.
A10: 7 | B10: Strokovna verifikacija | C10: Pred objavo naj točko pregleda vsebinski/strokovni partner (npr. Dolenjski muzej/ZVKDS glede na dogovor).
A11: 8 | B11: Objava | C11: Status 'Objavljeno' šele, ko je vsebina javna, QR testiran in dokazila arhivirana.
A12: 9 | B12: Etape | C12: Razporeditev po 8 etapah je V1. Satelitski kraki so pripisani najbližji operativni etapi in zahtevajo GIS/terensko potrditev.
